Workbook

Sheet 일반 관리비
A1: 웰스타임 관리사무소
A3: 평당 관리비 | G3: 4000 | H3: 원
A5: 매장명 | D5: 분양 평수 | F5: 일반 관리비 | H5: 비고
A6: 원유로 | D6: 44 | F6: =D6*G3 -> 176000
A7: 와플칸 | D7: 10 | F7: =D7*G3 -> 40000
A8: 에바돈카츠 | D8: 31 | F8: =D8*G3 -> 124000
A9: 드림스터디 | D9: 207 | F9: =D9*G3 -> 828000
A10: 아기고래 | D10: 62 | F10: =D10*G3 -> 248000
A11: 카카오3F | D11: 207 | F11: =D11*G3 -> 828000
A12: 영종 스크린4F | D12: 207 | F12: =D12*G3 -> 828000
A13: 명성화로 | D13: 207 | F13: =D13*G3 -> 828000
A14: 코프라독스 | D14: 31 | F14: =D14*G3 -> 124000
A15: 합계 | D15: =SUM(D6:D14) -> 1006 | F15: =SUM(F6:F14) -> 4024000

Sheet 수도비용
A1: 웰스타임 관리사무소 2026 / 07월 공동 수도료
C3: 전체사용 | E3: 세대사용 | G3: 공용사용
A4: 사용량 | C4: 301 | E4: =D21 -> 115 | G4: =C4-E4 -> 186 | K4: 세대 사용요금 | N4: 단위 요금 * 세대 사용량
A5: 사용 기간 | C5: 04.22 - 05.21 | K5: 공용 사용량 | N5: 전체 사용량 - 세대 사용량
A6: 검침일 | C6: 21 | E6: 일 | K6: 단위요금 | N6: 납기요금 / 전체 사용량
A7: 납기 요금 | C7: 960100 | E7: =F21 -> 366815.61 | G7: =C7-E7 -> 593284.39
A8: 단위 요금 | C8: =C7/C4 -> 3189.701
A11: 세대요금 | D11: 사용량 | F11: 세대사용요금 | I11: 공용지분율 | K11: 공용사용요금 | M11: 합계요금
A12: 원유로 | D12: 9 | F12: =D12*C8 -> 28707.309 | I12: 0.044 | K12: =I12*G7 -> 26104.513 | M12: =F12+K12 -> 54811.822
A13: 필이발소 | D13: 9 | F13: =D13*C8 -> 28707.309 | I13: 0.009 | K13: =I13*G7 -> 5339.5595 | M13: =F13+K13 -> 34046.868
A14: 에바돈카츠 | D14: 45 | F14: =D14*C8 -> 143536.54 | I14: 0.031 | K14: =I14*G7 -> 18391.816 | M14: =F14+K14 -> 161928.36
A15: 드림스터디 | D15: 3 | F15: =D15*C8 -> 9569.103 | I15: 0.207 | K15: =I15*G7 -> 122809.87 | M15: =F15+K15 -> 132378.97
A16: 아기고래 | D16: 11 | F16: =D16*C8 -> 35086.711 | I16: 0.062 | K16: =I16*G7 -> 36783.632 | M16: =F16+K16 -> 71870.343
A17: 카카오 스크린 3F | D17: 6 | F17: =D17*C8 -> 19138.206 | I17: 0.207 | K17: =I17*G7 -> 122809.87 | M17: =F17+K17 -> 141948.07
A18: 영종 스크린 4F | D18: 0 | F18: =D18*C8 -> 0 | I18: 0.207 | K18: =I18*G7 -> 122809.87 | M18: =F18+K18 -> 122809.87
A19: 명성화로 | D19: 32 | F19: =D19*C8 -> 102070.43 | I19: 0.207 | K19: =I19*G7 -> 122809.87 | M19: =F19+K19 -> 224880.3
A20: 코브라독스 | D20: 0 | F20: =D20*C8 -> 0 | I20: 0.026 | K20: =I20*G7 -> 15425.394 | M20: =F20+K20 -> 15425.394
A21: 합계 | D21: =SUM(D12:D20) -> 115 | F21: =SUM(F12:F20) -> 366815.61 | I21: =SUM(I12:I20) -> 1 | K21: =SUM(K12:K20) -> 593284.39 | M21: =F21+K21 -> 960100

Sheet 전기비용
A1: 웰스타임 관리사무소 2026 / 07 월 공동 전기료 | N1: 검침일 | O1: 04일
B3: 기본 요금 | D3: 전기요금 | I3: 전력기금 | K3: 당월요금 | M3: 사용기간
B4: 203280 | D4: 562270 | I4: 18790 | K4: =SUM(B4,D4,I4) -> 784340 | M4: 06.05 - 07.03
A7: 세대요금 | D7: 기본요금 | F7: 전력량요금 | I7: 전력기금 | K7: 공용지분률 | M7: 합계요금
A8: 원유로 | D8: =B4*K8 -> 8944.32 | F8: =D4*K8 -> 24739.88 | I8: =I4*K8 -> 826.76 | K8: 0.044 | M8: =SUM(D8,F8,I8) -> 34510.96
A9: 필이발소 | D9: =B4*K9 -> 1829.52 | F9: =D4*K9 -> 5060.43 | I9: =I4*K9 -> 169.11 | K9: 0.009 | M9: =SUM(D9,F9,I9) -> 7059.06
A10: 에바돈카츠 | D10: =B4*K10 -> 6301.68 | F10: =D4*K10 -> 17430.37 | I10: =I4*K10 -> 582.49 | K10: 0.031 | M10: =SUM(D10,F10,I10) -> 24314.54
A11: 드림스터디 | D11: =B4*K11 -> 42078.96 | F11: =D4*K11 -> 116389.89 | I11: =I4*K11 -> 3889.53 | K11: 0.207 | M11: =SUM(D11,F11,I11) -> 162358.38
A12: 아기고래 | D12: =B4*K12 -> 12603.36 | F12: =D4*K12 -> 34860.74 | I12: =I4*K12 -> 1164.98 | K12: 0.062 | M12: =SUM(D12,F12,I12) -> 48629.08
A13: 카카오 스크린 3F | D13: =B4*K13 -> 42078.96 | F13: =D4*K13 -> 116389.89 | I13: =I4*K13 -> 3889.53 | K13: 0.207 | M13: =SUM(D13,F13,I13) -> 162358.38
A14: 영종 스크린 4F | D14: =B4*K14 -> 42078.96 | F14: =D4*K14 -> 116389.89 | I14: =I4*K14 -> 3889.53 | K14: 0.207 | M14: =SUM(D14,F14,I14) -> 162358.38
A15: 명성화로 | D15: =B4*K15 -> 42078.96 | F15: =D4*K15 -> 116389.89 | I15: =I4*K15 -> 3889.53 | K15: 0.207 | M15: =SUM(D15,F15,I15) -> 162358.38
A16: 코브라독스 | D16: =B4*K16 -> 5285.28 | F16: =D4*K16 -> 14619.02 | I16: =I4*K16 -> 488.54 | K16: 0.026 | M16: =SUM(D16,F16,I16) -> 20392.84
A17: 합계 | D17: =SUM(D8:D16) -> 203280 | F17: =SUM(F8:F16) -> 562270 | I17: =SUM(I8:I16) -> 18790 | K17: =SUM(K8:K16) -> 1 | M17: =SUM(M8:M16) -> 784340

Sheet 통합비용
A1: 웰스타임 2026년 7월 공동 수도료
C2: 세대사용 | D2: 공용사용
A3: 전체사용량 | B3: =수도비용!C4 -> 301 | C3: =수도비용!E4 -> 115 | D3: =B3-C3 -> 186
A4: 사용기간 | B4: 05.22 - 06.21
A5: 검침일 | B5: =수도비용!C6 -> 21
A6: 납기요금 | B6: =수도비용!C7 -> 960100 | C6: =수도비용!E7 -> 366815.61 | D6: =B6-C6 -> 593284.39
A7: 단위요금 | B7: =B6/B3 -> 3189.701
A9: 세대요금 | B9: 사용량 | C9: 세대사용요금 | F9: 공용지분율 | G9: 공용사용요금 | H9: 합계요금
A10: 원유로 | B10: =수도비용!D12 -> 9 | C10: =수도비용!F12 -> 28707.309 | F10: =수도비용!I12 -> 0.044 | G10: =D6*F10 -> 26104.513 | H10: =C10+G10 -> 54811.822
A11: 와플칸 | B11: =수도비용!D13 -> 9 | C11: =수도비용!F13 -> 28707.309 | F11: =수도비용!I13 -> 0.009 | G11: =D6*F11 -> 5339.5595 | H11: =C11+G11 -> 34046.868
A12: 에바돈카츠 | B12: =수도비용!D14 -> 45 | C12: =수도비용!F14 -> 143536.54 | F12: =수도비용!I14 -> 0.031 | G12: =D6*F12 -> 18391.816 | H12: =C12+G12 -> 161928.36
A13: 드림스터디 | B13: =수도비용!D15 -> 3 | C13: =수도비용!F15 -> 9569.103 | F13: =수도비용!I15 -> 0.207 | G13: =D6*F13 -> 122809.87 | H13: =C13+G13 -> 132378.97
A14: 아기고래 | B14: =수도비용!D16 -> 11 | C14: =수도비용!F16 -> 35086.711 | F14: =수도비용!I16 -> 0.062 | G14: =D6*F14 -> 36783.632 | H14: =C14+G14 -> 71870.343
A15: 카카오3F | B15: =수도비용!D17 -> 6 | C15: =수도비용!F17 -> 19138.206 | F15: =수도비용!I17 -> 0.207 | G15: =D6*F15 -> 122809.87 | H15: =SUM(C15,G15) -> 141948.07
A16: 영종 스크린4F | B16: =수도비용!D18 -> 0 | C16: =수도비용!F18 -> 0 | F16: =수도비용!I18 -> 0.207 | G16: =D6*F16 -> 122809.87 | H16: =C16+G16 -> 122809.87
A17: 고기나라 | B17: =수도비용!D19 -> 32 | C17: =수도비용!F19 -> 102070.43 | F17: =수도비용!I19 -> 0.207 | G17: =D6*F17 -> 122809.87 | H17: =C17+G17 -> 224880.3
A18: 코브라독스 | B18: =수도비용!D20 -> 0 | C18: =수도비용!F20 -> 0 | F18: =수도비용!I20 -> 0.026 | G18: =D6*F18 -> 15425.394 | H18: =C18+G18 -> 15425.394
A19: 합계 | B19: =SUM(B10:B18) -> 115 | C19: =SUM(C10:C18) -> 366815.61 | F19: =SUM(F10:F18) -> 1 | G19: =SUM(G10:G18) -> 593284.39 | H19: =SUM(H10:H18) -> 960100
C21: 세대사용요금 | D21: 단위요금*세대사용량
C22: 공용사용량 | D22: 전체사용량-세대사용량
C23: 단위요금 | D23: 납기요금/전체사용량
A25: 웰스타임 2026년 7월 공동 전기료 | H25: 검침일 04일
B26: 기본요금 | C26: 전력량요금 | F26: 전력기금 | G26: 당월요금 | H26: 사용기간
B27: =전기비용!B4 -> 203280 | C27: =전기비용!D4 -> 562270 | F27: =전기비용!I4 -> 18790 | G27: =전기비용!K4 -> 784340 | H27: =전기비용!M4 -> 06.05 - 07.03
A29: 세대요금 | B29: 기본요금 | C29: 전력량요금 | F29: 전력기금 | G29: 공용지분율 | H29: 합계요금
A30: 원유로 | B30: =전기비용!D8 -> 8944.32 | C30: =전기비용!F8 -> 24739.88 | F30: =전기비용!I8 -> 826.76 | G30: =전기비용!K8 -> 0.044 | H30: =전기비용!M8 -> 34510.96
A31: 와플칸 | B31: =전기비용!D9 -> 1829.52 | C31: =전기비용!F9 -> 5060.43 | F31: =전기비용!I9 -> 169.11 | G31: =전기비용!K9 -> 0.009 | H31: =전기비용!M9 -> 7059.06
A32: 에바돈카츠 | B32: =전기비용!D10 -> 6301.68 | C32: =전기비용!F10 -> 17430.37 | F32: =전기비용!I10 -> 582.49 | G32: =전기비용!K10 -> 0.031 | H32: =전기비용!M10 -> 24314.54
A33: 드림스터디 | B33: =전기비용!D11 -> 42078.96 | C33: =전기비용!F11 -> 116389.89 | F33: =전기비용!I11 -> 3889.53 | G33: =전기비용!K11 -> 0.207 | H33: =전기비용!M11 -> 162358.38
A34: 아기고래 | B34: =전기비용!D12 -> 12603.36 | C34: =전기비용!F12 -> 34860.74 | F34: =전기비용!I12 -> 1164.98 | G34: =전기비용!K12 -> 0.062 | H34: =전기비용!M12 -> 48629.08
A35: 카카오4F | B35: =전기비용!D13 -> 42078.96 | C35: =전기비용!F13 -> 116389.89 | F35: =전기비용!I13 -> 3889.53 | G35: =전기비용!K13 -> 0.207 | H35: =전기비용!M13 -> 162358.38
A36: 카카오3F | B36: =전기비용!D14 -> 42078.96 | C36: =전기비용!F14 -> 116389.89 | F36: =전기비용!I14 -> 3889.53 | G36: =전기비용!K14 -> 0.207 | H36: =전기비용!M14 -> 162358.38
A37: 고기나라 | B37: =전기비용!D15 -> 42078.96 | C37: =전기비용!F15 -> 116389.89 | F37: =전기비용!I15 -> 3889.53 | G37: =전기비용!K15 -> 0.207 | H37: =전기비용!M15 -> 162358.38
A38: 코브라독스 | B38: =전기비용!D16 -> 5285.28 | C38: =전기비용!F16 -> 14619.02 | F38: =전기비용!I16 -> 488.54 | G38: =전기비용!K16 -> 0.026 | H38: =전기비용!M16 -> 20392.84
A39: 합계 | B39: =전기비용!D17 -> 203280 | C39: =전기비용!F17 -> 562270 | F39: =SUM(F30:F38) -> 18790 | G39: =SUM(G30:G38) -> 1 | H39: =SUM(H30:H38) -> 784340
B42: 분양평수 | C42: 일반관리비 | F42: 일반관리비 | G42: 평당 | H42: 4000
A43: 원유로 | B43: ='일반 관리비'!D6 -> 44 | C43: ='일반 관리비'!F6 -> 176000
A44: 와플칸 | B44: ='일반 관리비'!D7 -> 10 | C44: ='일반 관리비'!F7 -> 40000
A45: 에바돈카츠 | B45: ='일반 관리비'!D8 -> 31 | C45: ='일반 관리비'!F8 -> 124000
A46: 드림스터디 | B46: ='일반 관리비'!D9 -> 207 | C46: ='일반 관리비'!F9 -> 828000
...

Sheet 에바돈카츠
A1: 관리비 납입 영수증 (입주자용)
A5: 2026 | C5: 년 | D5: 7 | E5: 월 | F5: 101 | L5: 호 | M5: 에바돈카츠 | Q5: 귀하
A8: 일반관리비 | D8: =통합비용!C45 -> 124000 | H8: 세대상수도료 | K8: =통합비용!C12 -> 143536.54 | O8: 당월부과액계
A10: 관리비 부가세 | D10: =D8*10% -> 12400 | H10: 수도이용량 | K10: =통합비용!B12 -> 45 | O10: =SUM(K8,K12,K14,K18,K20,K24,D8,D10,D12,D14,D16,D18,D20,D22,D24,D26) -> 325742.9
A12: 청소비 | D12: 0 | H12: 물이용부담 | K12: 0 | O12: 미납액
A14: 소독비 | D14: 0 | H14: 전기(공용) | K14: =통합비용!H32 -> 24314.54
A16: 수선유지비 | D16: 0 | O16: 미납연체료
A18: 승강기보험료 | D18: 0 | H18: 청소비품 | K18: 3100
A20: 화재보험료 | D20: 0 | H20: 승강기안전검사 | O20: 납기내금액
A22: 공동전기료 | D22: 0 | O22: =SUM(O10,O14,O18) -> 325742.9
A24: 승강기전기료 | D24: 0 | H24: 소방안전관리 | K24: 0 | O24: 연체료(%)
A26: 공동수도료 | D26: =통합비용!G12 -> 18391.816 | O26: 1.5
A28: 납부기한 | O28: 납기후금액
A29: 2026. 07. 30
O30: 0
M33: 위 금액을 영수하였습니다.
A38: 웰스타임 관리사무소
A40: 신협 137-010-094596 유성진 (웰스타임)

Sheet 코브라독스
A1: 관리비 납입 영수증 (입주자용)
A5: 2026 | C5: 년 | D5: 6 | E5: 월 | F5: 102 | L5: 호 | M5: 코브라독스 | Q5: 귀하
A8: 일반관리비 | D8: =통합비용!C51 -> 124000 | H8: 세대상수도료 | K8: =통합비용!C18 -> 0 | O8: 당월부과액계
A10: 관리비 부가세 | D10: =D8*10% -> 12400 | H10: 수도이용량 | K10: =통합비용!B18 -> 0 | O10: =SUM(K8,K12,K14,K18,K20,K24,D8,D10,D12,D14,D16,D18,D20,D22,D24,D26) -> 173538.23
A12: 청소비 | D12: 0 | H12: 물이용부담 | K12: 0 | O12: 미납액
A14: 소독비 | D14: 0 | H14: 전기(공용) | K14: =통합비용!H38 -> 20392.84 | O14: 0
A16: 수선유지비 | D16: 0 | O16: 미납연체료
A18: 승강기보험료 | D18: 0 | H18: 청소비품 | K18: 1320 | O18: 0
A20: 화재보험료 | D20: 0 | H20: 전기안전관리 | K20: 0 | O20: 납기내금액
A22: 공동전기료 | D22: 0 | O22: =SUM(O10,O14,O18) -> 173538.23
A24: 승강기전기료 | D24: 0 | H24: 소방안전관리 | K24: 0 | O24: 연체료(%)
A26: 공동수도료 | D26: =통합비용!G18 -> 15425.394 | O26: 1.5
A28: 납부기한 | O28: 납기후금액
A29: 2026. 06. 30
O30: 0
M33: 위 금액을 영수하였습니다.
A38: 웰스타임 관리사무소
A40: 신협 137-010-094596 유성진 (웰스타임)

Sheet 아기고래
A1: 관리비 납입 영수증 (입주자용)
A5: 2026 | C5: 년 | D5: 7 | E5: 월 | F5: 103 | L5: 호 | M5: 아기고래 | Q5: 귀하
A8: 일반관리비 | D8: =통합비용!C47 -> 248000 | H8: 세대상수도료 | K8: =통합비용!C14 -> 35086.711 | O8: 당월부과액계
A10: 관리비 부가세 | D10: =D8*10% -> 24800 | H10: 수도이용량 | K10: =통합비용!B14 -> 11 | O10: =SUM(K8,K12,K14,K18,K20,K24,D8,D10,D12,D14,D16,D18,D20,D22,D24,D26) -> 395939.42
A12: 청소비 | D12: 0 | H12: 물이용부담 | K12: 0 | O12: 미납액
A14: 소독비 | D14: 0 | H14: 전기(공용) | K14: =통합비용!H34 -> 48629.08 | O14: 0
A16: 수선유지비 | D16: 0 | O16: 미납연체료
A18: 승강기보험료 | D18: 0 | H18: 청소비품 | K18: 2640 | O18: 0
A20: 화재보험료 | D20: 0 | H20: 가스안전검사 | K20: 0 | O20: 납기내금액
A22: 공동전기료 | D22: 0 | O22: =SUM(O10,O14,O18) -> 395939.42
A24: 승강기전기료 | D24: 0 | H24: 소방안전관리 | K24: 0 | O24: 연체료(%)
A26: 공동수도료 | D26: =통합비용!G14 -> 36783.632 | O26: 1.5
A28: 납부기한 | O28: 납기후금액
A29: 2026. 07. 30
O30: 0
M33: 위 금액을 영수하였습니다.
A38: 웰스타임 관리사무소
A40: 신협 137-010-094596 유성진 (웰스타임)

Sheet 원유로
A1: 관리비 납입 영수증 (입주자용)
A5: 2026 | C5: 년 | D5: 7 | E5: 월 | F5: 105 | L5: 호 | M5: 원유로 | Q5: 귀하
A9: 일반관리비 | D9: =통합비용!C43 -> 176000 | H9: 세대상수도료 | K9: =통합비용!C10 -> 28707.309 | O9: 당월부과액계
A11: 관리비 부가세 | D11: =D9*10% -> 17600 | H11: 수도이용량 | K11: =통합비용!B10 -> 9 | O11: =SUM(K9,K13,K15,K19,K21,K25,D9,D11,D13,D15,D17,D19,D21,D23,D25,D27) -> 287322.78
A13: 청소비 | D13: 0 | H13: 물이용부담 | K13: 0 | O13: 미납액
A15: 소독비 | D15: 0 | H15: 전기(공용) | K15: =통합비용!H30 -> 34510.96 | O15: 0
A17: 수선유지비 | D17: 0 | O17: 미납연체료
A19: 승강기보험료 | D19: 0 | H19: 청소비품 | K19: 4400 | O19: 0
A21: 화재보험료 | D21: 0 | H21: 승강기안전관리 | K21: 0 | O21: 납기내금액
A23: 공동전기료 | D23: 0 | O23: =SUM(O11,O15,O19) -> 287322.78
A25: 승강기전기료 | D25: 0 | H25: 소방안전관리 | K25: 0 | O25: 연체료(%)
A27: 공동수도료 | D27: =통합비용!G10 -> 26104.513 | O27: 1.5
A29: 납부기한 | O29: 납기후금액
A30: 2026. 07. 30
O31: 0
M34: 위 금액을 영수하였습니다.
A39: 웰스타임 관리사무소
A41: 신협 137-010-094596 유성진 (웰스타임)

Sheet 와플칸
A1: 관리비 납입 영수증 (입주자용)
A5: 2026 | C5: 년 | D5: 7 | E5: 월 | F5: 108 | L5: 호 | M5: 필이발소 | Q5: 귀하
A8: 일반관리비 | D8: =통합비용!C44 -> 40000 | H8: 세대상수도료 | K8: =통합비용!C11 -> 28707.309 | O8: 당월부과액계
A10: 관리비 부가세 | D10: 0 | H10: 수도이용량 | K10: =통합비용!B11 -> 9 | O10: =SUM(K8,K12,K14,K18,K20,K24,D8,D10,D12,D14,D16,D18,D20,D22,D24,D26) -> 82425.928
A12: 청소비 | D12: 0 | H12: 물이용부담 | K12: 0 | O12: 미납액
A14: 소독비 | D14: 0 | H14: 전기(공용) | K14: =통합비용!H31 -> 7059.06 | O14: 0
A16: 수선유지비 | D16: 0 | O16: 미납연체료
A18: 승강기보험료 | D18: 0 | H18: 청소비품 | K18: 1320 | O18: 0
A20: 화재보험료 | D20: 0 | H20: 전기안전관리 | K20: 0 | O20: 납기내금액
A22: 공동전기료 | D22: 0 | O22: =SUM(O10,O14,O18) -> 82425.928
A24: 승강기전기료 | D24: 0 | H24: 소방안전관리 | K24: 0 | O24: 연체료(%)
A26: 공동수도료 | D26: =통합비용!G11 -> 5339.5595 | O26: 1.5
A28: 납부기한 | O28: 납기후금액
A29: 2026. 07. 30
O30: 0
M33: 위 금액을 영수하였습니다.
A38: 웰스타임 관리사무소
A40: 신협 137-010-094596 유성진 (웰스타임)

Sheet 명성화로2F
A1: 관리비 납입 영수증 (입주자용)
A5: 2026 | C5: 년 | D5: 7 | E5: 월 | F5: 201~203 | L5: 호 | M5: 명성화로 | Q5: 귀하
A8: 일반관리비 | D8: =통합비용!C50 -> 828000 | H8: 세대상수도료 | K8: =통합비용!C17 -> 102070.43 | O8: 당월부과액계
A10: 관리비 부가세 | D10: =D8*10% -> 82800 | H10: 수도이용량 | K10: =통합비용!B17 -> 32 | O10: =SUM(K8,K12,K14,K18,K20,K24,D8,D10,D12,D14,D16,D18,D20,D22,D24,D26) -> 1317638.7
A12: 청소비 | D12: 0 | H12: 물이용부담 | K12: 0 | O12: 미납액
A14: 소독비 | D14: 0 | H14: 전기(공용) | K14: =통합비용!H37 -> 162358.38 | O14: 8053063
A16: 수선유지비 | D16: 0 | O16: 미납연체료
A18: 승강기보험료 | D18: 0 | H18: 청소비품 | K18: 19600 | O18: 120795
A20: 화재보험료 | D20: 0 | H20: 승강기사용점검 | K20: 0 | O20: 납기내금액
A22: 공동전기료 | D22: 0 | O22: =SUM(O10,O14,O18) -> 9491496.7
A24: 승강기전기료 | D24: 0 | H24: 소방안전관리 | K24: 0 | O24: 연체료(%)
A26: 공동수도료 | D26: =통합비용!G17 -> 122809.87 | O26: 1.5
A28: 납부기한 | O28: 납기후금액
A29: 2026. 07. 30
O30: 0
M33: 위 금액을 영수하였습니다.
A38: 웰스타임 관리사무소
A40: 신협 137-010-094596 유성진 (웰스타임)

Sheet 카카오 스크린3F
A1: 관리비 납입 영수증 (입주자용)
A5: 2026 | C5: 년 | D5: 7 | E5: 월 | F5: 301 | L5: 호 | M5: 카카오 | Q5: 귀하
A8: 일반관리비 | D8: =통합비용!C49 -> 828000 | H8: 세대상수도료 | K8: =통합비용!C15 -> 19138.206 | O8: 당월부과액계
A10: 관리비 부가세 | D10: =D8*10% -> 82800 | H10: 수도이용량 | K10: =통합비용!B15 -> 6 | O10: =SUM(K8,K12,K14,K18,K20,K24,D8,D10,D12,D14,D16,D18,D20,D22,D24,D26,K22) -> 1234706.5
A12: 청소비 | D12: 0 | H12: 물이용부담 | K12: 0 | O12: 미납액
A14: 소독비 | D14: 0 | H14: 전기(공용) | K14: =통합비용!H36 -> 162358.38 | O14: 0
A16: 수선유지비 | D16: 0 | O16: 미납연체료
A18: 승강기보험료 | D18: 0 | H18: 청소비품 | K18: 19600 | O18: 0
A20: 화재보험료 | D20: 0 | H20: 가스안전검사 | K20: 0 | O20: 납기내금액
A22: 공동전기료 | D22: 0 | H22: 유지보수비 | O22: =SUM(O10,O14,O18) -> 1234706.5
A24: 승강기전기료 | D24: 0 | H24: 소방안전관리 | K24: 0 | O24: 연체료(%)
A26: 공동수도료 | D26: =통합비용!G15 -> 122809.87 | O26: 1.5
A28: 납부기한 | O28: 납기후금액
A29: 2026. 07. 30
O30: 0
M33: 위 금액을 영수하였습니다.
A38: 웰스타임 관리사무소
A40: 신협 137-010-094596 유성진 (웰스타임)

Sheet 영종스크린 4F
A1: 관리비 납입 영수증 (입주자용)
A5: 2026 | C5: 년 | D5: 7 | E5: 월 | F5: 401 | L5: 호 | M5: 영종스크린 | Q5: 귀하
A8: 일반관리비 | D8: =통합비용!C49 -> 828000 | H8: 세대상수도료 | K8: =통합비용!C16 -> 0 | O8: 당월부과액계
A10: 관리비 부가세 | D10: =D8*10% -> 82800 | H10: 수도이용량 | K10: =통합비용!B16 -> 0 | O10: =SUM(K8,K12,K14,K18,K20,K24,D8,D10,D12,D14,D16,D18,D20,D22,D24,D26,K22) -> 1215568.2
A12: 청소비 | D12: 0 | H12: 물이용부담 | K12: 0 | O12: 미납액
A14: 소독비 | D14: 0 | H14: 전기(공용) | K14: =통합비용!H36 -> 162358.38 | O14: 0
A16: 수선유지비 | D16: 0 | O16: 미납연체료
A18: 승강기보험료 | D18: 0 | H18: 청소비품 | K18: 19600 | O18: 0
A20: 화재보험료 | D20: 0 | H20: 승강기안전검사 | K20: 0 | O20: 납기내금액
A22: 공동전기료 | D22: 0 | H22: 유지보수비 | O22: =SUM(O10,O14,O18) -> 1215568.2
A24: 승강기전기료 | D24: 0 | H24: 소방안전관리 | K24: 0 | O24: 연체료(%)
A26: 공동수도료 | D26: =통합비용!G16 -> 122809.87 | O26: 1.5
A28: 납부기한 | O28: 납기후금액
A29: 2026. 07. 30
O30: 0
M33: 위 금액을 영수하였습니다.
A38: 웰스타임 관리사무소
A40: 신협 137-010-094596 유성진 (웰스타임)

Sheet 드림스터디
A1: 관리비 납입 영수증 (입주자용)
A5: 2026 | C5: 년 | D5: 7 | E5: 월 | F5: 501 | L5: 호 | M5: 드림스터디 | Q5: 귀하
A8: 일반관리비 | D8: =통합비용!C46 -> 828000 | H8: 세대상수도료 | K8: =통합비용!C13 -> 9569.103 | O8: 당월부과액계
A10: 관리비 부가세 | D10: =D8*10% -> 82800 | H10: 수도이용량 | K10: =통합비용!B13 -> 3 | O10: =SUM(K8,K12,K14,K18,K20,K24,D8,D10,D12,D14,D16,D18,D20,D22,D24,D26) -> 1225137.4
A12: 청소비 | D12: 0 | H12: 물이용부담 | K12: 0 | O12: 미납액
A14: 소독비 | D14: 0 | H14: 전기(공용) | K14: =통합비용!H33 -> 162358.38 | O14: 6723770
A16: 수선유지비 | D16: 0 | O16: 미납연체료
A18: 승강기보험료 | D18: 0 | H18: 청소비품 | K18: 19600 | O18: 100856
A20: 화재보험료 | D20: 0 | H20: 승강기안전관리 | K20: 0 | O20: 납기내금액
A22: 공동전기료 | D22: 0 | O22: =SUM(O10,O14,O18) -> 8049763.4
A24: 승강기전기료 | D24: 0 | H24: 소방안전관리 | K24: 0 | O24: 연체료(%)
A26: 공동수도료 | D26: =통합비용!G13 -> 122809.87 | O26: 1.5
A28: 납부기한 | O28: 납기후금액
A29: 2026. 07. 30
O30: 0
M33: 위 금액을 영수하였습니다.
A38: 웰스타임 관리사무소
A40: 신협 137-010-094596 유성진 (웰스타임)

Sheet Sheet1
